{"uuid": "bc7e9e50-1379-4b47-b2d9-765c69f0165f", "children": ["ab72efbc-a00e-40e8-9f76-6381add00be3"], "befores": [{"name": "login_page", "status": "broken", "statusDetails": {"message": "urllib3.exceptions.MaxRetryError: HTTPConnectionPool(host='localhost', port=52499): Max retries exceeded with url: /session/d18e63a9a08fd96af379a13b4da8b1bf/url (Caused by NewConnectionError('<urllib3.connection.HTTPConnection object at 0x000001707B6FE1F0>: Failed to establish a new connection: [WinError 10061] No connection could be made because the target machine actively refused it'))\n", "trace": "  File \"C:\\Users\\PC\\PycharmProjects\\teambook\\venv\\lib\\site-packages\\pluggy\\_callers.py\", line 39, in _multicall\n    res = hook_impl.function(*args)\n  File \"C:\\Users\\PC\\PycharmProjects\\teambook\\venv\\lib\\site-packages\\_pytest\\fixtures.py\", line 1130, in pytest_fixture_setup\n    result = call_fixture_func(fixturefunc, request, kwargs)\n  File \"C:\\Users\\PC\\PycharmProjects\\teambook\\venv\\lib\\site-packages\\_pytest\\fixtures.py\", line 909, in call_fixture_func\n    fixture_result = fixturefunc(**kwargs)\n  File \"C:\\Users\\PC\\PycharmProjects\\teambook\\conftest.py\", line 45, in login_page\n    page.load()\n  File \"C:\\Users\\PC\\PycharmProjects\\teambook\\pages\\login_page.py\", line 19, in load\n    self.browser.get(self.url)\n  File \"C:\\Users\\PC\\PycharmProjects\\teambook\\venv\\lib\\site-packages\\selenium\\webdriver\\remote\\webdriver.py\", line 449, in get\n    self.execute(Command.GET, {\"url\": url})\n  File \"C:\\Users\\PC\\PycharmProjects\\teambook\\venv\\lib\\site-packages\\selenium\\webdriver\\remote\\webdriver.py\", line 438, in execute\n    response = self.command_executor.execute(driver_command, params)\n  File \"C:\\Users\\PC\\PycharmProjects\\teambook\\venv\\lib\\site-packages\\selenium\\webdriver\\remote\\remote_connection.py\", line 290, in execute\n    return self._request(command_info[0], url, body=data)\n  File \"C:\\Users\\PC\\PycharmProjects\\teambook\\venv\\lib\\site-packages\\selenium\\webdriver\\remote\\remote_connection.py\", line 311, in _request\n    response = self._conn.request(method, url, body=body, headers=headers)\n  File \"C:\\Users\\PC\\PycharmProjects\\teambook\\venv\\lib\\site-packages\\urllib3\\request.py\", line 78, in request\n    return self.request_encode_body(\n  File \"C:\\Users\\PC\\PycharmProjects\\teambook\\venv\\lib\\site-packages\\urllib3\\request.py\", line 170, in request_encode_body\n    return self.urlopen(method, url, **extra_kw)\n  File \"C:\\Users\\PC\\PycharmProjects\\teambook\\venv\\lib\\site-packages\\urllib3\\poolmanager.py\", line 376, in urlopen\n    response = conn.urlopen(method, u.request_uri, **kw)\n  File \"C:\\Users\\PC\\PycharmProjects\\teambook\\venv\\lib\\site-packages\\urllib3\\connectionpool.py\", line 815, in urlopen\n    return self.urlopen(\n  File \"C:\\Users\\PC\\PycharmProjects\\teambook\\venv\\lib\\site-packages\\urllib3\\connectionpool.py\", line 815, in urlopen\n    return self.urlopen(\n  File \"C:\\Users\\PC\\PycharmProjects\\teambook\\venv\\lib\\site-packages\\urllib3\\connectionpool.py\", line 815, in urlopen\n    return self.urlopen(\n  File \"C:\\Users\\PC\\PycharmProjects\\teambook\\venv\\lib\\site-packages\\urllib3\\connectionpool.py\", line 787, in urlopen\n    retries = retries.increment(\n  File \"C:\\Users\\PC\\PycharmProjects\\teambook\\venv\\lib\\site-packages\\urllib3\\util\\retry.py\", line 592, in increment\n    raise MaxRetryError(_pool, url, error or ResponseError(cause))\n"}, "start": 1698097688401, "stop": 1698097704723}], "start": 1698097688401, "stop": 1698097704972}